<?xml version="1.0"?>
<sdf version="1.5">

 <model name="riley_robot">
  <pose>0.0 0.0 0.0 0.0 0.0 0.0</pose>
  
  <link name="base_footprint">
  	
  </link>

  <joint name="base_link_joint" type="fixed">
    <parent> base_link</parent>
    <child> base_footprint </child>
    <pose> 0 0 -0.126 0 0 0 </pose>
  </joint>
  
  <link name="base_link">
    <inertial>
      <pose>0 0 -0.126 0 0 0 </pose>
      <mass> 0.317289185919371</mass>
      <inertia>
        <ixx>0.000970876188779837</ixx>
        <ixy>6.94113413553014E-10</ixy>
        <ixz>3.51219781695308E-06</ixz>
        <iyy>0.00067590401119229</iyy>
        <iyz>9.43089820999509E-10</iyz>
        <izz>0.00152301084809347</izz>
      </inertia>  
    </inertial>
    <collision name='base_link_collision'>
      <pose>0 0 -0.126 1.57 0 0</pose>
      <geometry>
        <box>
            <size>0.085 0.230 0.096</size>
        </box>
      </geometry>
    </collision>
    <visual name='base_link_visual'>
      <pose>0 0 -0.126 1.57 0 0</pose>
      <geometry>
        <mesh> 
             <uri>model://riley/meshes/MiddlepartV2.STL</uri>
             <scale> 0.5 0.5 0.5</scale>
        </mesh> 
      </geometry>
    </visual>
  </link>
  
  <link name="tail_link">
    <collision name='tail_link_colission'>
      <pose>-0.093 0.0 -0.0115 0 0 0</pose>
      <geometry>
        <box>
            <size>0.100 0.06 0.019</size>
        </box>
      </geometry>
    </collision>
    <visual name='tail_link_visual'>
      <pose>-0.093 0.0 -0.0115 0 0 0</pose>
      <geometry>
        <mesh> 
             <uri>model://riley/meshes/MiddlepartTailV2.STL</uri>
             <scale> 0.5 0.5 0.5</scale>
        </mesh> 
      </geometry>
    </visual>
  </link>
  
  <joint name="tail_link_joint" type="fixed">
    <pose>-0.093 0.0 -0.0115 0 0 0</pose>
    <parent>base_link</parent>
    <child>tail_link</child>
  </joint>
  
  <link name="back_wheel">
    <collision name='back_wheel_collision'>
      <pose>-0.04 0.0 -0.039 0 0 0</pose>
      <geometry>
        <sphere>
               <radius>0.03</radius>
        </sphere>
      </geometry>
      <surface>
          <friction>
             <ode>
                 <mu>0.0</mu>
                 <mu2>0.0</mu2>
             </ode>
          </friction>
      </surface>
    </collision>
    <visual name='back_wheel_visual'>
      <pose>-0.04 0.0 -0.039 0 0 0</pose>
      <geometry>
        <mesh> 
             <uri>model://riley/meshes/SwivelWheel-SwivelWheelWheel-1.STL</uri>
             <scale> 0.5 0.5 0.5</scale>
        </mesh> 
      </geometry>
    </visual>
  </link>
  
  <joint name="back_wheel_joint" type="ball">
    <parent>tail_link</parent>
    <child>back_wheel</child>
    <pose>-0.04 0.0 -0.039 0 0 0</pose>
  </joint>
  
    <link name="left_wheel">
      <inertial>
        <pose>0 0.115 -0.01575 1.57 0 0</pose>
        <mass>0.215731682367034</mass>
        <inertia>
          <ixx>0.000257596806184402</ixx>
          <ixy>1.66478787417013E-11</ixy>
          <ixz>-1.003412444624E-10</ixz>
          <iyy>0.00045223817291695</iyy>
          <iyz>-1.15162210593445E-11</iyz>
          <izz>0.00025759686320202</izz>
        </inertia>  
      </inertial>
      <collision name="left_wheel_collision">
        <pose>0 0.115 -0.01575 1.57 0 0</pose>
        <geometry>
          <cylinder> 
              <radius>0.063</radius> 
              <length>0.044</length>
          </cylinder>
        </geometry>
        <surface>
            <friction>
               <ode>
                   <mu>0.9</mu>
                   <mu2>0.9</mu2>
               </ode>
            </friction>
        </surface>
      </collision>
      <visual name="left_wheel_visual">
        <pose>0 0.115 -0.01575 1.57 0 0</pose>
        <geometry>
          <mesh> 
             <uri>model://riley/meshes/ReelyBuggyWheel_Left.STL</uri>
             <scale> 0.5 0.5 0.5</scale>
          </mesh>
        </geometry>
      </visual>
    </link>
    
    <link name="right_wheel">
      <inertial>
        <pose>0 -0.115 -0.01575 1.57 0 0</pose>
        <mass>0.215732042845507</mass>
        <inertia>
          <ixx>0.00025759718782391</ixx>
          <ixy>2.12843584581061E-11</ixy>
          <ixz>-5.66299342939977E-12</ixz>
          <iyy>0.000452238839696424</iyy>
          <iyz>3.99311464604179E-12</iyz>
          <izz>0.000257597229543076</izz>
        </inertia>  
      </inertial>
      <collision name="right_wheel_collision">
        <pose>0 -0.115 -0.01575 1.57 0 0</pose>
        <geometry>
          <cylinder> 
             <radius>0.063</radius> 
             <length>0.044</length>
          </cylinder>   
        </geometry>
        <surface>
            <friction>
               <ode>
                   <mu>0.9</mu>
                   <mu2>0.9</mu2>
               </ode>
            </friction>
        </surface>
      </collision>
      <visual name="right_wheel_visual">
        <pose>0 -0.115 -0.01575 1.57 0 0</pose>
        <geometry>
          <mesh> 
             <uri>model://riley/meshes/ReelyBuggyWheel_Right.STL</uri>
             <scale> 0.5 0.5 0.5</scale>
          </mesh>  
        </geometry>
      </visual>
    </link>
    
    <joint name="left_wheel_joint" type="revolute">
      <axis> 
           <xyz>0 1 0</xyz>
      </axis>
      <limit>
              <effort>0.25</effort>
      </limit>
      <parent>base_link</parent>
      <child>left_wheel</child>
      <pose>-0.0005 0.140 -0.01575 1.57 0 0</pose>
    </joint>
    
    <joint name="right_wheel_joint" type="revolute">
      <axis> 
           <xyz>0 1 0 0 0 0</xyz>
      </axis>
      <limit>
           <effort>0.25</effort>
      </limit>
      <parent>base_link</parent>
      <child>right_wheel</child>
      <pose>-0.0005 -0.140 -0.01575 1.57 0 0</pose>
    </joint>
    

<link name="imu_link">
  
  <collision name="imu_link_collision">
    <pose>0 0.01 0</pose>
    <geometry>
      <box> 
          <size>0.05 0.05 0.05</size>
      </box>
    </geometry>
  </collision>
  <visual name="imu_link_visual">
    <pose>0 0.01 0</pose>
    <geometry>
      <mesh> 
         <uri>model://riley/meshes/IMU.STL</uri>
         <scale> 0.5 0.5 0.5</scale>
      </mesh>  
    </geometry>
  </visual>
  <sensor name="imu_sensor" type="imu">
    <always_on>true</always_on>
    <update_rate>100</update_rate>
    <visualize>true</visualize>
    <pose>0 0.01 0</pose>
    <imu>
      <angular_velocity>
        <x>
          <noise type="gaussian">
            <mean>0.0</mean>
            <stddev>2e-4</stddev>
            <bias_mean>0.0000075</bias_mean>
            <bias_stddev>0.0000008</bias_stddev>
          </noise>
        </x>
        <y>
          <noise type="gaussian">
            <mean>0.0</mean>
            <stddev>2e-4</stddev>
            <bias_mean>0.0000075</bias_mean>
            <bias_stddev>0.0000008</bias_stddev>
          </noise>
        </y>
        <z>
          <noise type="gaussian">
            <mean>0.0</mean>
            <stddev>2e-4</stddev>
            <bias_mean>0.0000075</bias_mean>
            <bias_stddev>0.0000008</bias_stddev>
          </noise>
        </z>
      </angular_velocity>
      <linear_acceleration>
        <x>
          <noise type="gaussian">
            <mean>0.0</mean>
            <stddev>1.7e-2</stddev>
            <bias_mean>0.1</bias_mean>
            <bias_stddev>0.001</bias_stddev>
          </noise>
        </x>
        <y>
          <noise type="gaussian">
            <mean>0.0</mean>
            <stddev>1.7e-2</stddev>
            <bias_mean>0.1</bias_mean>
            <bias_stddev>0.001</bias_stddev>
          </noise>
        </y>
        <z>
          <noise type="gaussian">
            <mean>0.0</mean>
            <stddev>1.7e-2</stddev>
            <bias_mean>0.1</bias_mean>
            <bias_stddev>0.001</bias_stddev>
          </noise>
        </z>
      </linear_acceleration>
    </imu>
    <plugin filename="libgazebo_ros_imu_sensor.so" name="imu_plugin">
      <ros>
        <remapping>~/out:=imu</remapping>
      </ros>
      <initial_orientation_as_reference>false</initial_orientation_as_reference>
    </plugin>
  </sensor>
</link>

<joint name="imu_joint" type="fixed">
  <parent>base_link</parent>
  <child>imu_link</child>
  <pose>0 0.01 0</pose>
  <axis>
     <xyz>0 1 0</xyz>
  </axis>
</joint>


  <plugin name='riley_diff_drive' filename='libgazebo_ros_diff_drive.so'>
    <update_rate>50</update_rate>
    <ros>
       <remapping>/tf:=tf</remapping>
    </ros>

    <!-- wheels -->
    <left_joint>left_wheel_joint</left_joint>
    <right_joint>right_wheel_joint</right_joint>

    <!-- kinematics -->
    <wheel_separation>0.4</wheel_separation>
    <wheel_diameter>0.126</wheel_diameter>

    <!-- limits -->
    <max_wheel_torque>2</max_wheel_torque>
    <max_wheel_acceleration>1.0</max_wheel_acceleration>
    <command_topic>cmd_vel</command_topic>
   

    <!-- output -->
    <publish_odom>true</publish_odom>
    <publish_odom_tf>true</publish_odom_tf>
    <publish_wheel_tf>false</publish_wheel_tf>
    
    <odometry_topic>odom</odometry_topic>
    <odometry_frame>odom</odometry_frame>
    <robot_base_frame>base_link</robot_base_frame>
  </plugin>



  <plugin name="riley_joint_state" filename="libgazebo_ros_joint_state_publisher.so">
    <ros>
       <remapping>~/out:=joint_states</remapping>
    </ros>
    <update_rate>50</update_rate>
    <joint_name>left_wheel_joint</joint_name>
    <joint_name>right_wheel_joint</joint_name>
  </plugin>


 <link name="lidar_link">
    <inertial>
      <pose>0 0 0.054 0 0 0</pose>
      <mass>0.125</mass>
      <inertia> 
             <ixx>0.001</ixx>
             <ixy>0</ixy>
             <ixz>0</ixz> 
             <iyy>0.001</iyy>
             <iyz>0</iyz>
             <izz>0.001</izz>
      </inertia>
    </inertial>
    <collision name="lidar_link_collision">
      <pose>0 0 0.054 0 0 0</pose>
      <geometry>
         <cylinder>
                  <radius>0.018</radius> 
                  <length>0.03</length>
         </cylinder>
      </geometry>
    </collision>
    <visual name="lidar_link_visual">
      <pose>0 0 0.054 0 0 0</pose>
      <geometry>
         <mesh> 
           <uri>model://riley/meshes/Lidar.STL</uri>
           <scale> 0.5 0.5 0.5</scale>
         </mesh>  
      </geometry>
    </visual>
    <sensor name="lidar" type="ray">
      <always_on>true</always_on>
      <visualize>false</visualize>
      <pose>0 0 0.054 0 0 0</pose>
      <update_rate>10</update_rate>
      <ray>
        <scan>
          <horizontal>
            <samples>360</samples>
            <resolution>1.000000</resolution>
            <min_angle>0.000000</min_angle>
            <max_angle>6.280000</max_angle>
          </horizontal>
        </scan>
        <range>
          <min>0.120000</min>
          <max>3.5</max>
          <resolution>0.015000</resolution>
        </range>
        <noise>
          <type>gaussian</type>
          <mean>0.0</mean>
          <stddev>0.01</stddev>
        </noise>
      </ray>
      <plugin name="riley_laserscan" filename="libgazebo_ros_ray_sensor.so">
        <ros>
          <remapping>~/out:=scan</remapping>
        </ros>
        <output_type>sensor_msgs/LaserScan</output_type>
        <frame_name>lidar_link</frame_name>
      </plugin>
    </sensor>
  </link>
    
  <joint name="lidar_joint" type="fixed">
    <parent>base_link</parent>
    <child>lidar_link</child>
    <pose>0 0 0.054 0 0 0</pose>
  </joint>
    
  <link name="camera_link">
    <inertial>
      <pose>0.045 0 0.03 0 0 0</pose>
      <mass>0.035</mass>
      <inertia> 
              <ixx>0.001</ixx>
              <ixy>0</ixy>
              <ixz>0</ixz>
              <iyy>0.001</iyy>
              <iyz>0</iyz> 
              <izz>0.001</izz>
      </inertia>
    </inertial>
    <collision name="camera_link_collision">
      <pose>0.045 0 0.03 0 0 0</pose>
      <geometry>
        <box>
            <size>0.005 0.0050 0.0050</size>
        </box>
      </geometry>
    </collision>
    <visual name="camera_link_visual">
      <pose>0.045 0 0.03 0 0 0</pose>
      <geometry>
        <mesh> 
           <uri>model://riley/meshes/Camera.STL</uri>
           <scale> 0.5 0.5 0.5</scale>
        </mesh>  
      </geometry>
    </visual>
  </link>
  
  <joint name="camera_joint" type="fixed">
    <parent>base_link</parent>
    <child>camera_link</child>
    <pose>0.045 0 0.03 0 0 0</pose>
    <axis>
       <xyz>0 1 0</xyz>
    </axis>
  </joint>

  <link name="camera_depth_frame"/>

  <joint name="camera_depth_joint" type="fixed">
    <pose>0 0 0 -1.57 0 -1.57</pose>
    <parent>camera_link</parent>
    <child>camera_depth_frame</child>
    <axis>
       <xyz>0 1 0</xyz>
    </axis>
  </joint>

    <sensor name="depth_camera" type="depth">
      <visualize>true</visualize>
      <update_rate>30.0</update_rate>
      <camera name="camera">
        <horizontal_fov>1.047198</horizontal_fov>
        <image>
          <width>640</width>
          <height>480</height>
          <format>R8G8B8</format>
        </image>
        <clip>
          <near>0.05</near>
          <far>3</far>
        </clip>
      </camera>
      <plugin name="depth_camera_controller" filename="libgazebo_ros_camera.so">
        <baseline>0.2</baseline>
        <alwaysOn>true</alwaysOn>
        <updateRate>0.0</updateRate>
        <frame_name>camera_depth_frame</frame_name>
        <pointCloudCutoff>0.5</pointCloudCutoff>
        <pointCloudCutoffMax>3.0</pointCloudCutoffMax>
        <distortionK1>0</distortionK1>
        <distortionK2>0</distortionK2>
        <distortionK3>0</distortionK3>
        <distortionT1>0</distortionT1>
        <distortionT2>0</distortionT2>
        <CxPrime>0</CxPrime>
        <Cx>0</Cx>
        <Cy>0</Cy>
        <focalLength>0</focalLength>
        <hackBaseline>0</hackBaseline>
      </plugin>
    </sensor>

 </model>
</sdf>



